<?xml version="1.0"?>
<robot xmlns:xacro="http://ros.org/wiki/xacro">

  <!--
    Author: Jimy Zhang <jimy.zhang@umbratek.com> <jimy92@163.com>
    Contributers:
  -->

  <xacro:macro name="utra4_450_urdf" params="prefix
    joint1_lower_limit:=${-2.0*pi} joint1_upper_limit:=${2.0*pi}
    joint2_lower_limit:=${-2.0*pi} joint2_upper_limit:=${2.0*pi}
    joint3_lower_limit:=${-2.0*pi} joint3_upper_limit:=${2.0*pi}
    joint4_lower_limit:=${-100.0*pi} joint4_upper_limit:=${100.0*pi}">

    <material name="Black">  <color rgba="0.0 0.0 0.0 1.0"/> </material>
    <material name="Red">    <color rgba="0.8 0.0 0.0 1.0"/> </material>
    <material name="White">  <color rgba="1.0 1.0 1.0 1.0"/> </material>
    <material name="Silver"> <color rgba="0.7 0.7 0.7 1.0"/> </material>

    <xacro:macro name="origin_joint1"> <origin xyz="0 0 0" rpy="0 0 0" /> </xacro:macro>
    <xacro:macro name="origin_joint2"> <origin xyz="0.1995 0 0.129" rpy="0 0 0" /> </xacro:macro>
    <xacro:macro name="origin_joint3"> <origin xyz="0.123 0 -0.13" rpy="0 0 0" /> </xacro:macro>
    <xacro:macro name="origin_joint4"> <origin xyz="0.0778 0 0" rpy="0 0 0" /> </xacro:macro>

    <xacro:macro name="origin_visual_base">  <origin xyz="0 0 0" rpy="0 0 0" /> </xacro:macro>
    <xacro:macro name="origin_visual_link_1"> <origin xyz="0 0 0" rpy="0 0 0" /> </xacro:macro>
    <xacro:macro name="origin_visual_link_2"> <origin xyz="0 0 0" rpy="0 0 0" /> </xacro:macro>
    <xacro:macro name="origin_visual_link_3"> <origin xyz="0 0 0" rpy="0 0 0" /> </xacro:macro>
    <xacro:macro name="origin_visual_link_4"> <origin xyz="0 0 0" rpy="0 0 0" /> </xacro:macro>

    <xacro:macro name="origin_inertial_base">  <origin xyz="0 0 0" rpy="0 0 0" /> </xacro:macro>
    <xacro:macro name="origin_inertial_link_1"> <origin xyz="0 0 0" rpy="0 0 0" /> </xacro:macro>
    <xacro:macro name="origin_inertial_link_2"> <origin xyz="0 0 0" rpy="0 0 0" /> </xacro:macro>
    <xacro:macro name="origin_inertial_link_3"> <origin xyz="0 0 0" rpy="0 0 0" /> </xacro:macro>
    <xacro:macro name="origin_inertial_link_4"> <origin xyz="0 0 0" rpy="0 0 0" /> </xacro:macro>

    <xacro:macro name="inertia_base">  <inertia ixx="0" ixy="0" ixz="0" iyy="0" iyz="0" izz="0" /> </xacro:macro>
    <xacro:macro name="inertia_link_1"> <inertia ixx="0" ixy="0" ixz="0" iyy="0" iyz="0" izz="0" /> </xacro:macro>
    <xacro:macro name="inertia_link_2"> <inertia ixx="0" ixy="0" ixz="0" iyy="0" iyz="0" izz="0" /> </xacro:macro>
    <xacro:macro name="inertia_link_3"> <inertia ixx="0" ixy="0" ixz="0" iyy="0" iyz="0" izz="0" /> </xacro:macro>
    <xacro:macro name="inertia_link_4"> <inertia ixx="0" ixy="0" ixz="0" iyy="0" iyz="0" izz="0" /> </xacro:macro>

    <xacro:property name="mass_base"  value="0.00001" />
    <xacro:property name="mass_link_1" value="0.00001" />
    <xacro:property name="mass_link_2" value="0.00001" />
    <xacro:property name="mass_link_3" value="0.00001" />
    <xacro:property name="mass_link_4" value="0.00001" />

    <xacro:property name="effort_joint1" value="0" />
    <xacro:property name="effort_joint2" value="0" />
    <xacro:property name="effort_joint3" value="1000" />
    <xacro:property name="effort_joint4" value="0" />

    <xacro:property name="damping_joint1" value="0" />
    <xacro:property name="damping_joint2" value="0" />
    <xacro:property name="damping_joint3" value="0.4" />
    <xacro:property name="damping_joint4" value="0" />

    <xacro:property name="friction_joint1" value="0" />
    <xacro:property name="friction_joint2" value="0" />
    <xacro:property name="friction_joint3" value="5" />
    <xacro:property name="friction_joint4" value="0" />

    <link name="${prefix}base_link">
      <inertial>
        <xacro:origin_inertial_base/>
        <mass value="${mass_base}" />
        <xacro:inertia_base/>
      </inertial>
      <visual>
        <xacro:origin_visual_base/>
        <geometry> <mesh filename="package://utra_description/meshes/utra4_450/visual/base.STL" /> </geometry>
        <material name="Silver" />
      </visual>
      <collision>
        <xacro:origin_visual_base/>
        <geometry> <mesh filename="package://utra_description/meshes/utra4_450/visual/base.STL" /> </geometry>
      </collision>
    </link>

    <joint name="${prefix}joint1" type="revolute">
      <xacro:origin_joint1/>
      <parent link="${prefix}base_link" />
      <child link="${prefix}link_1" />
      <axis xyz="0 0 -1" />
      <limit lower="${joint1_lower_limit}" upper="${joint1_upper_limit}" effort="${effort_joint1}" velocity="3.14" />
      <dynamics damping="${damping_joint1}" friction="${friction_joint1}" />
    </joint>

    <link name="${prefix}link_1">
      <inertial>
        <xacro:origin_inertial_link_1/>
        <mass value="${mass_link_1}" />
        <xacro:inertia_link_1/>
      </inertial>
      <visual>
        <xacro:origin_visual_link_1/>
        <geometry> <mesh filename="package://utra_description/meshes/utra4_450/visual/link1.STL" /> </geometry>
        <material name="Silver" />
      </visual>
      <collision>
        <xacro:origin_visual_link_1/>
        <geometry> <mesh filename="package://utra_description/meshes/utra4_450/visual/link1.STL" /> </geometry>
      </collision>
    </link>

    <joint name="${prefix}joint2" type="revolute">
      <xacro:origin_joint2/>
      <parent link="${prefix}link_1" />
      <child link="${prefix}link_2" />
      <axis xyz="0 0 -1" />
      <limit lower="${joint2_lower_limit}" upper="${joint2_upper_limit}" effort="${effort_joint2}" velocity="3.14" />
      <dynamics damping="${damping_joint2}" friction="${friction_joint2}" />
    </joint>

    <link name="${prefix}link_2">
      <inertial>
        <xacro:origin_inertial_link_2/>
        <mass value="${mass_link_2}" />
        <xacro:inertia_link_2/>
      </inertial>
      <visual>
        <xacro:origin_visual_link_2/>
        <geometry> <mesh filename="package://utra_description/meshes/utra4_450/visual/link2.STL" /> </geometry>
        <material name="Silver" />
      </visual>
      <collision>
        <xacro:origin_visual_link_2/>
        <geometry> <mesh filename="package://utra_description/meshes/utra4_450/visual/link2.STL" /> </geometry>
      </collision>
    </link>

    <joint name="${prefix}joint3" type="prismatic">
      <xacro:origin_joint3/>
      <parent link="${prefix}link_2" />
      <child link="${prefix}link_3" />
      <axis xyz="0 0 1" />
      <limit lower="-0.2" upper="0.8" effort="${effort_joint3}" velocity="3.14" />
      <dynamics damping="${damping_joint3}" friction="${friction_joint3}" />
    </joint>

    <link name="${prefix}link_3">
      <inertial>
        <xacro:origin_inertial_link_3/>
        <mass value="${mass_link_3}" />
        <xacro:inertia_link_3/>
      </inertial>
      <visual>
        <xacro:origin_visual_link_3/>
        <geometry> <mesh filename="package://utra_description/meshes/utra4_450/visual/link3.STL" /> </geometry>
        <material name="Silver" />
      </visual>
      <collision>
        <xacro:origin_visual_link_3/>
        <geometry> <mesh filename="package://utra_description/meshes/utra4_450/visual/link3.STL" /> </geometry>
      </collision>
    </link>

    <joint name="${prefix}joint4" type="revolute">
      <xacro:origin_joint4/>
      <parent link="${prefix}link_3" />
      <child link="${prefix}link_4" />
      <axis xyz="0 0 1" />
      <limit lower="-10000000000" upper="10000000000" effort="${effort_joint4}" velocity="3.14" />
      <dynamics damping="${damping_joint4}" friction="${friction_joint4}" />
    </joint>

    <link name="${prefix}link_4">
      <inertial>
        <xacro:origin_inertial_link_4/>
        <mass value="${mass_link_4}" />
        <xacro:inertia_link_4/>
      </inertial>
      <visual>
        <xacro:origin_visual_link_4/>
        <geometry> <mesh filename="package://utra_description/meshes/utra4_450/visual/link4.STL" /> </geometry>
        <material name="Silver" />
      </visual>
      <collision>
        <xacro:origin_visual_link_4/>
        <geometry> <mesh filename="package://utra_description/meshes/utra4_450/visual/link4.STL" /> </geometry>
      </collision>
    </link>

  </xacro:macro>
</robot>
